<mujoco model="ant">
  <compiler angle="degree" coordinate="local" inertiafromgeom="true"/>
  <!-- timestep = 0.01  -->
  <option integrator="RK4" timestep="0.05"/> 
  <custom>
    <numeric data="0.0 0.0 0.55 1.0 0.0 0.0 0.0 0.0 1.0 0.0 -1.0 0.0 -1.0 0.0 1.0" name="init_qpos"/>
  </custom>
  <default>
    <joint armature="1" damping="1" limited="true"/>
    <geom conaffinity="0" condim="3" density="5.0" friction="1 0.5 0.5" margin="0.01" rgba="0.8 0.6 0.4 1"/>
  </default>
  <asset>
    <texture builtin="gradient" height="100" rgb1="1 1 1" rgb2="0 0 0" type="skybox" width="100"/>
    <texture builtin="flat" height="1278" mark="cross" markrgb="1 1 1" name="texgeom" random="0.01" rgb1="0.8 0.6 0.4" rgb2="0.8 0.6 0.4" type="cube" width="127"/>
    <texture builtin="checker" height="100" name="texplane" rgb1="0 0 0" rgb2="0.8 0.8 0.8" type="2d" width="100"/>
    <material name="MatPlane" reflectance="0.5" shininess="1" specular="1" texrepeat="60 60" texture="texplane"/>
    <material name="geom" texture="texgeom" texuniform="true"/>

    <mesh name="mesh_Plate" file="mesh_stl/Plate.stl"/>
    <mesh name="mesh_Pole1" file="mesh_stl/Pole1.stl"/>
    <mesh name="mesh_Pole2" file="mesh_stl/Pole2.stl"/>
    <mesh name="mesh_Pole3" file="mesh_stl/Pole3.stl"/>
    <mesh name="mesh_Pole4" file="mesh_stl/Pole4.stl"/>
    <mesh name="mesh_Wire.001" file="mesh_stl/Wire.001.stl"/>
    <mesh name="mesh_Wire.002" file="mesh_stl/Wire.002.stl"/>
    <mesh name="mesh_Wire.000" file="mesh_stl/Wire.000.stl"/>
    <mesh name="mesh_Wire.003" file="mesh_stl/Wire.003.stl"/>
    <mesh name="mesh_Wire.004" file="mesh_stl/Wire.004.stl"/>
    <mesh name="mesh_Wire.005" file="mesh_stl/Wire.005.stl"/>
    <mesh name="mesh_Wire.006" file="mesh_stl/Wire.006.stl"/>
    <mesh name="mesh_Wire.007" file="mesh_stl/Wire.007.stl"/>
    <mesh name="mesh_Wire.008" file="mesh_stl/Wire.008.stl"/>
    <mesh name="mesh_Wire.010" file="mesh_stl/Wire.010.stl"/>
    <mesh name="mesh_Wire.011" file="mesh_stl/Wire.011.stl"/>
    <mesh name="mesh_Wire.009" file="mesh_stl/Wire.009.stl"/>
    <mesh name="mesh_Wire.012" file="mesh_stl/Wire.012.stl"/>
  </asset>
  <worldbody>
    <light cutoff="100" diffuse="1 1 1" dir="-0 0 -1.3" directional="true" exponent="1" pos="0 0 1.3" specular=".1 .1 .1"/>
    <geom conaffinity="1" condim="3" material="MatPlane" name="floor" pos="0 0 0" rgba="0.8 0.9 0.8 1" size="40 40 40" type="plane"/>
    
    <!-- <body name="box" pos="10 -10 1.5">
        <geom type="box" size="0.1 0.1 0.1" rgba="1 0 0 1"/>
    </body> -->
    <!-- from ring.xml -->
    <!-- 0.0 -> -0.03 -->
    <body name="Plate" pos="0.0 0.0 0.0" quat="1.0 0.0 0.0 0.0">
        <geom name="Plate" type="mesh" pos="0 0 0" quat="1 0 0 0" rgba="1.0 1.0 1.0 1.0" mass="1.0" contype="1" conaffinity="1" mesh="mesh_Plate"/>
        <body name="Pole1" pos="7.0 7.0 3.0" quat="1.0 0.0 0.0 0.0">
            <geom name="Pole1" type="mesh" pos="0 0 0" quat="1 0 0 0" rgba="1.0 1.0 1.0 1.0" mass="1.0" contype="1" conaffinity="1" mesh="mesh_Pole1"/>
        </body>
        <body name="Pole2" pos="-7.0 7.0 3.0" quat="1.0 0.0 0.0 0.0">
            <geom name="Pole2" type="mesh" pos="0 0 0" quat="1 0 0 0" rgba="1.0 1.0 1.0 1.0" mass="1.0" contype="1" conaffinity="1" mesh="mesh_Pole2"/>
        </body>
        <body name="Pole3" pos="-7.0 -7.0 3.0" quat="1.0 0.0 0.0 0.0">
            <geom name="Pole3" type="mesh" pos="0 0 0" quat="1 0 0 0" rgba="1.0 1.0 1.0 1.0" mass="1.0" contype="1" conaffinity="1" mesh="mesh_Pole3"/>
        </body>
        <body name="Pole4" pos="7.0 -7.0 3.0" quat="1.0 0.0 0.0 0.0">
            <geom name="Pole4" type="mesh" pos="0 0 0" quat="1 0 0 0" rgba="1.0 1.0 1.0 1.0" mass="1.0" contype="1" conaffinity="1" mesh="mesh_Pole4"/>
        </body>
        <body name="WirePath.001" pos="0.0 0.0 0.0" quat="1.0 0.0 0.0 0.0">
            <geom name="WirePath.001" type="mesh" pos="0 0 0" quat="1 0 0 0" rgba="1.0 1.0 1.0 1.0" mass="1.0" contype="1" conaffinity="1" mesh="mesh_Wire.001"/>
        </body>
        <body name="WirePath.002" pos="0.0 0.0 0.0" quat="1.0 0.0 0.0 0.0">
            <geom name="WirePath.002" type="mesh" pos="0 0 0" quat="1 0 0 0" rgba="1.0 1.0 1.0 1.0" mass="1.0" contype="1" conaffinity="1" mesh="mesh_Wire.002"/>
        </body>
        <body name="WirePath.000" pos="0.0 0.0 0.0" quat="1.0 0.0 0.0 0.0">
            <geom name="WirePath.000" type="mesh" pos="0 0 0" quat="1 0 0 0" rgba="1.0 1.0 1.0 1.0" mass="1.0" contype="1" conaffinity="1" mesh="mesh_Wire.000"/>
        </body>
        <body name="WirePath.003" pos="0.0 0.0 0.0" quat="0.7071068286895752 0.0 0.0 -0.7071067094802856">
            <geom name="WirePath.003" type="mesh" pos="0 0 0" quat="1 0 0 0" rgba="1.0 1.0 1.0 1.0" mass="1.0" contype="1" conaffinity="1" mesh="mesh_Wire.003"/>
        </body>
        <body name="WirePath.004" pos="0.0 0.0 0.0" quat="0.7071068286895752 0.0 0.0 -0.7071067094802856">
            <geom name="WirePath.004" type="mesh" pos="0 0 0" quat="1 0 0 0" rgba="1.0 1.0 1.0 1.0" mass="1.0" contype="1" conaffinity="1" mesh="mesh_Wire.004"/>
        </body>
        <body name="WirePath.005" pos="0.0 0.0 0.0" quat="0.7071068286895752 0.0 0.0 -0.7071067094802856">
            <geom name="WirePath.005" type="mesh" pos="0 0 0" quat="1 0 0 0" rgba="1.0 1.0 1.0 1.0" mass="1.0" contype="1" conaffinity="1" mesh="mesh_Wire.005"/>
        </body>
        <body name="WirePath.006" pos="14.0 0.0 0.0" quat="0.7071068286895752 0.0 0.0 -0.7071067094802856">
            <geom name="WirePath.006" type="mesh" pos="0 0 0" quat="1 0 0 0" rgba="1.0 1.0 1.0 1.0" mass="1.0" contype="1" conaffinity="1" mesh="mesh_Wire.006"/>
        </body>
        <body name="WirePath.007" pos="14.0 0.0 0.0" quat="0.7071068286895752 0.0 0.0 -0.7071067094802856">
            <geom name="WirePath.007" type="mesh" pos="0 0 0" quat="1 0 0 0" rgba="1.0 1.0 1.0 1.0" mass="1.0" contype="1" conaffinity="1" mesh="mesh_Wire.007"/>
        </body>
        <body name="WirePath.008" pos="14.0 0.0 0.0" quat="0.7071068286895752 0.0 0.0 -0.7071067094802856">
            <geom name="WirePath.008" type="mesh" pos="0 0 0" quat="1 0 0 0" rgba="1.0 1.0 1.0 1.0" mass="1.0" contype="1" conaffinity="1" mesh="mesh_Wire.008"/>
        </body>
        <body name="WirePath.010" pos="0.0 14.0 0.0" quat="1.0 0.0 0.0 0.0">
            <geom name="WirePath.010" type="mesh" pos="0 0 0" quat="1 0 0 0" rgba="1.0 1.0 1.0 1.0" mass="1.0" contype="1" conaffinity="1" mesh="mesh_Wire.010"/>
        </body>
        <body name="WirePath.011" pos="0.0 14.0 0.0" quat="1.0 0.0 0.0 0.0">
            <geom name="WirePath.011" type="mesh" pos="0 0 0" quat="1 0 0 0" rgba="1.0 1.0 1.0 1.0" mass="1.0" contype="1" conaffinity="1" mesh="mesh_Wire.011"/>
        </body>
        <body name="WirePath.009" pos="14.0 0.0 0.0" quat="0.7071068286895752 0.0 0.0 -0.7071067094802856">
            <geom name="WirePath.009" type="mesh" pos="0 0 0" quat="1 0 0 0" rgba="1.0 1.0 1.0 1.0" mass="1.0" contype="1" conaffinity="1" mesh="mesh_Wire.009"/>
        </body>
        <body name="WirePath.012" pos="0.0 14.0 0.0" quat="1.0 0.0 0.0 0.0">
            <geom name="WirePath.012" type="mesh" pos="0 0 0" quat="1 0 0 0" rgba="1.0 1.0 1.0 1.0" mass="1.0" contype="1" conaffinity="1" mesh="mesh_Wire.012"/>
        </body>
    </body>
    <!--  -->

    <body name="torso" pos="0 0 5">
      <camera name="track" mode="trackcom" pos="0 -3 0.3" xyaxes="1 0 0 0 0 1"/>
      <geom name="torso_geom" pos="0 0 0" size="0.25" type="sphere"/>
      <joint armature="0" damping="0" limited="false" margin="0.01" name="root" pos="0 0 0" type="free"/>
      <body name="front_left_leg" pos="0 0 0">
        <geom fromto="0.0 0.0 0.0 0.2 0.2 0.0" name="aux_1_geom" size="0.08" type="capsule"/>
        <body name="aux_1" pos="0.2 0.2 0">
          <joint axis="0 0 1" name="hip_1" pos="0.0 0.0 0.0" range="-30 30" type="hinge"/>
          <geom fromto="0.0 0.0 0.0 0.2 0.2 0.0" name="left_leg_geom" size="0.08" type="capsule"/>
          <body pos="0.2 0.2 0">
            <joint axis="-1 1 0" name="ankle_1" pos="0.0 0.0 0.0" range="30 70" type="hinge"/>
            <geom fromto="0.0 0.0 0.0 0.4 0.4 0.0" name="left_ankle_geom" size="0.08" type="capsule"/>
          </body>
        </body>
      </body>
      <body name="front_right_leg" pos="0 0 0">
        <geom fromto="0.0 0.0 0.0 -0.2 0.2 0.0" name="aux_2_geom" size="0.08" type="capsule"/>
        <body name="aux_2" pos="-0.2 0.2 0">
          <joint axis="0 0 1" name="hip_2" pos="0.0 0.0 0.0" range="-30 30" type="hinge"/>
          <geom fromto="0.0 0.0 0.0 -0.2 0.2 0.0" name="right_leg_geom" size="0.08" type="capsule"/>
          <body pos="-0.2 0.2 0">
            <joint axis="1 1 0" name="ankle_2" pos="0.0 0.0 0.0" range="-70 -30" type="hinge"/>
            <geom fromto="0.0 0.0 0.0 -0.4 0.4 0.0" name="right_ankle_geom" size="0.08" type="capsule"/>
          </body>
        </body>
      </body>
      <body name="back_leg" pos="0 0 0">
        <geom fromto="0.0 0.0 0.0 -0.2 -0.2 0.0" name="aux_3_geom" size="0.08" type="capsule"/>
        <body name="aux_3" pos="-0.2 -0.2 0">
          <joint axis="0 0 1" name="hip_3" pos="0.0 0.0 0.0" range="-30 30" type="hinge"/>
          <geom fromto="0.0 0.0 0.0 -0.2 -0.2 0.0" name="back_leg_geom" size="0.08" type="capsule"/>
          <body pos="-0.2 -0.2 0">
            <joint axis="-1 1 0" name="ankle_3" pos="0.0 0.0 0.0" range="-70 -30" type="hinge"/>
            <geom fromto="0.0 0.0 0.0 -0.4 -0.4 0.0" name="third_ankle_geom" size="0.08" type="capsule"/>
          </body>
        </body>
      </body>
      <body name="right_back_leg" pos="0 0 0">
        <geom fromto="0.0 0.0 0.0 0.2 -0.2 0.0" name="aux_4_geom" size="0.08" type="capsule"/>
        <body name="aux_4" pos="0.2 -0.2 0">
          <joint axis="0 0 1" name="hip_4" pos="0.0 0.0 0.0" range="-30 30" type="hinge"/>
          <geom fromto="0.0 0.0 0.0 0.2 -0.2 0.0" name="rightback_leg_geom" size="0.08" type="capsule"/>
          <body pos="0.2 -0.2 0">
            <joint axis="1 1 0" name="ankle_4" pos="0.0 0.0 0.0" range="30 70" type="hinge"/>
            <geom fromto="0.0 0.0 0.0 0.4 -0.4 0.0" name="fourth_ankle_geom" size="0.08" type="capsule"/>
          </body>
        </body>
      </body>
    </body>
  </worldbody>
  <actuator>
    <motor ctrllimited="true" ctrlrange="-1.0 1.0" joint="hip_4" gear="150"/>
    <motor ctrllimited="true" ctrlrange="-1.0 1.0" joint="ankle_4" gear="150"/>
    <motor ctrllimited="true" ctrlrange="-1.0 1.0" joint="hip_1" gear="150"/>
    <motor ctrllimited="true" ctrlrange="-1.0 1.0" joint="ankle_1" gear="150"/>
    <motor ctrllimited="true" ctrlrange="-1.0 1.0" joint="hip_2" gear="150"/>
    <motor ctrllimited="true" ctrlrange="-1.0 1.0" joint="ankle_2" gear="150"/>
    <motor ctrllimited="true" ctrlrange="-1.0 1.0" joint="hip_3" gear="150"/>
    <motor ctrllimited="true" ctrlrange="-1.0 1.0" joint="ankle_3" gear="150"/>
  </actuator>
</mujoco>
